2018-03-23 21:04:53,851 ERROR: Exception on /index [GET] [in /home/ff7f/Desktop/microblog/flask/lib/python3.5/site-packages/flask/app.py:1560]
Traceback (most recent call last):
  File "/home/ff7f/Desktop/microblog/flask/lib/python3.5/site-packages/flask/app.py", line 1982, in wsgi_app
    response = self.full_dispatch_request()
  File "/home/ff7f/Desktop/microblog/flask/lib/python3.5/site-packages/flask/app.py", line 1614, in full_dispatch_request
    rv = self.handle_user_exception(e)
  File "/home/ff7f/Desktop/microblog/flask/lib/python3.5/site-packages/flask/app.py", line 1517, in handle_user_exception
    reraise(exc_type, exc_value, tb)
  File "/home/ff7f/Desktop/microblog/flask/lib/python3.5/site-packages/flask/_compat.py", line 33, in reraise
    raise value
  File "/home/ff7f/Desktop/microblog/flask/lib/python3.5/site-packages/flask/app.py", line 1612, in full_dispatch_request
    rv = self.dispatch_request()
  File "/home/ff7f/Desktop/microblog/flask/lib/python3.5/site-packages/flask/app.py", line 1598, in dispatch_request
    return self.view_functions[rule.endpoint](**req.view_args)
  File "/home/ff7f/Desktop/microblog/flask/lib/python3.5/site-packages/flask_login/utils.py", line 261, in decorated_view
    return func(*args, **kwargs)
  File "/home/ff7f/Desktop/microblog/app/routes.py", line 36, in index
    return render_template("index.html", title='Index page', posts=posts.items,next_url=next_url, prev_url=prev_url)
  File "/home/ff7f/Desktop/microblog/flask/lib/python3.5/site-packages/flask/templating.py", line 134, in render_template
    context, ctx.app)
  File "/home/ff7f/Desktop/microblog/flask/lib/python3.5/site-packages/flask/templating.py", line 116, in _render
    rv = template.render(context)
  File "/home/ff7f/Desktop/microblog/flask/lib/python3.5/site-packages/jinja2/environment.py", line 1008, in render
    return self.environment.handle_exception(exc_info, True)
  File "/home/ff7f/Desktop/microblog/flask/lib/python3.5/site-packages/jinja2/environment.py", line 780, in handle_exception
    reraise(exc_type, exc_value, tb)
  File "/home/ff7f/Desktop/microblog/flask/lib/python3.5/site-packages/jinja2/_compat.py", line 37, in reraise
    raise value.with_traceback(tb)
  File "/home/ff7f/Desktop/microblog/app/templates/index.html", line 1, in top-level template code
    {% extends "base.html" %}
  File "/home/ff7f/Desktop/microblog/app/templates/base.html", line 38, in top-level template code
    {% block content %}{% endblock %}
  File "/home/ff7f/Desktop/microblog/app/templates/index.html", line 6, in block "content"
    {{ form.hidden_tag() }}
  File "/home/ff7f/Desktop/microblog/flask/lib/python3.5/site-packages/jinja2/environment.py", line 430, in getattr
    return getattr(obj, attribute)
jinja2.exceptions.UndefinedError: 'form' is undefined
2018-03-23 21:07:27,429 INFO: Microblog startup [in /home/ff7f/Desktop/microblog/app/__init__.py:36]
2018-03-23 21:09:02,877 INFO: Microblog startup [in /home/ff7f/Desktop/microblog/app/__init__.py:36]
2018-03-23 21:10:53,096 INFO: Microblog startup [in /home/ff7f/Desktop/microblog/app/__init__.py:36]
2018-03-23 21:12:06,933 INFO: Microblog startup [in /home/ff7f/Desktop/microblog/app/__init__.py:36]
2018-03-23 21:13:05,156 INFO: Microblog startup [in /home/ff7f/Desktop/microblog/app/__init__.py:36]
2018-03-23 21:14:33,643 INFO: Microblog startup [in /home/ff7f/Desktop/microblog/app/__init__.py:36]
2018-03-23 21:20:07,569 INFO: Microblog startup [in /home/ff7f/Desktop/microblog/app/__init__.py:36]
2018-03-23 21:20:12,882 ERROR: Exception on /user/MegBegb [GET] [in /home/ff7f/Desktop/microblog/flask/lib/python3.5/site-packages/flask/app.py:1560]
Traceback (most recent call last):
  File "/home/ff7f/Desktop/microblog/flask/lib/python3.5/site-packages/flask/app.py", line 1982, in wsgi_app
    response = self.full_dispatch_request()
  File "/home/ff7f/Desktop/microblog/flask/lib/python3.5/site-packages/flask/app.py", line 1614, in full_dispatch_request
    rv = self.handle_user_exception(e)
  File "/home/ff7f/Desktop/microblog/flask/lib/python3.5/site-packages/flask/app.py", line 1517, in handle_user_exception
    reraise(exc_type, exc_value, tb)
  File "/home/ff7f/Desktop/microblog/flask/lib/python3.5/site-packages/flask/_compat.py", line 33, in reraise
    raise value
  File "/home/ff7f/Desktop/microblog/flask/lib/python3.5/site-packages/flask/app.py", line 1612, in full_dispatch_request
    rv = self.dispatch_request()
  File "/home/ff7f/Desktop/microblog/flask/lib/python3.5/site-packages/flask/app.py", line 1598, in dispatch_request
    return self.view_functions[rule.endpoint](**req.view_args)
  File "/home/ff7f/Desktop/microblog/flask/lib/python3.5/site-packages/flask_login/utils.py", line 261, in decorated_view
    return func(*args, **kwargs)
  File "/home/ff7f/Desktop/microblog/app/routes.py", line 127, in user
    posts = user.posts.order_by(Post.timestamp.desc()).paginate(page, app.config['POST_PER_PAGE'], False)
NameError: name 'page' is not defined
2018-03-23 21:20:46,271 INFO: Microblog startup [in /home/ff7f/Desktop/microblog/app/__init__.py:36]
2018-03-23 21:22:24,455 INFO: Microblog startup [in /home/ff7f/Desktop/microblog/app/__init__.py:36]
2018-03-23 21:23:16,805 INFO: Microblog startup [in /home/ff7f/Desktop/microblog/app/__init__.py:36]
2018-03-23 21:23:18,495 ERROR: Exception on /user/MegBegb [GET] [in /home/ff7f/Desktop/microblog/flask/lib/python3.5/site-packages/flask/app.py:1560]
Traceback (most recent call last):
  File "/home/ff7f/Desktop/microblog/flask/lib/python3.5/site-packages/flask/app.py", line 1982, in wsgi_app
    response = self.full_dispatch_request()
  File "/home/ff7f/Desktop/microblog/flask/lib/python3.5/site-packages/flask/app.py", line 1614, in full_dispatch_request
    rv = self.handle_user_exception(e)
  File "/home/ff7f/Desktop/microblog/flask/lib/python3.5/site-packages/flask/app.py", line 1517, in handle_user_exception
    reraise(exc_type, exc_value, tb)
  File "/home/ff7f/Desktop/microblog/flask/lib/python3.5/site-packages/flask/_compat.py", line 33, in reraise
    raise value
  File "/home/ff7f/Desktop/microblog/flask/lib/python3.5/site-packages/flask/app.py", line 1612, in full_dispatch_request
    rv = self.dispatch_request()
  File "/home/ff7f/Desktop/microblog/flask/lib/python3.5/site-packages/flask/app.py", line 1598, in dispatch_request
    return self.view_functions[rule.endpoint](**req.view_args)
  File "/home/ff7f/Desktop/microblog/flask/lib/python3.5/site-packages/flask_login/utils.py", line 261, in decorated_view
    return func(*args, **kwargs)
  File "/home/ff7f/Desktop/microblog/app/routes.py", line 129, in user
    next_url = url_for('user', page=posts.next_num)
  File "/home/ff7f/Desktop/microblog/flask/lib/python3.5/site-packages/flask/helpers.py", line 333, in url_for
    return appctx.app.handle_url_build_error(error, endpoint, values)
  File "/home/ff7f/Desktop/microblog/flask/lib/python3.5/site-packages/flask/app.py", line 1805, in handle_url_build_error
    reraise(exc_type, exc_value, tb)
  File "/home/ff7f/Desktop/microblog/flask/lib/python3.5/site-packages/flask/_compat.py", line 33, in reraise
    raise value
  File "/home/ff7f/Desktop/microblog/flask/lib/python3.5/site-packages/flask/helpers.py", line 323, in url_for
    force_external=external)
  File "/home/ff7f/Desktop/microblog/flask/lib/python3.5/site-packages/werkzeug/routing.py", line 1776, in build
    raise BuildError(endpoint, values, method, self)
werkzeug.routing.BuildError: Could not build url for endpoint 'user' with values ['page']. Did you forget to specify values ['username']?
2018-03-23 21:23:37,623 ERROR: Exception on /user/MegBegb [GET] [in /home/ff7f/Desktop/microblog/flask/lib/python3.5/site-packages/flask/app.py:1560]
Traceback (most recent call last):
  File "/home/ff7f/Desktop/microblog/flask/lib/python3.5/site-packages/flask/app.py", line 1982, in wsgi_app
    response = self.full_dispatch_request()
  File "/home/ff7f/Desktop/microblog/flask/lib/python3.5/site-packages/flask/app.py", line 1614, in full_dispatch_request
    rv = self.handle_user_exception(e)
  File "/home/ff7f/Desktop/microblog/flask/lib/python3.5/site-packages/flask/app.py", line 1517, in handle_user_exception
    reraise(exc_type, exc_value, tb)
  File "/home/ff7f/Desktop/microblog/flask/lib/python3.5/site-packages/flask/_compat.py", line 33, in reraise
    raise value
  File "/home/ff7f/Desktop/microblog/flask/lib/python3.5/site-packages/flask/app.py", line 1612, in full_dispatch_request
    rv = self.dispatch_request()
  File "/home/ff7f/Desktop/microblog/flask/lib/python3.5/site-packages/flask/app.py", line 1598, in dispatch_request
    return self.view_functions[rule.endpoint](**req.view_args)
  File "/home/ff7f/Desktop/microblog/flask/lib/python3.5/site-packages/flask_login/utils.py", line 261, in decorated_view
    return func(*args, **kwargs)
  File "/home/ff7f/Desktop/microblog/app/routes.py", line 129, in user
    next_url = url_for('user', page=posts.next_num)
  File "/home/ff7f/Desktop/microblog/flask/lib/python3.5/site-packages/flask/helpers.py", line 333, in url_for
    return appctx.app.handle_url_build_error(error, endpoint, values)
  File "/home/ff7f/Desktop/microblog/flask/lib/python3.5/site-packages/flask/app.py", line 1805, in handle_url_build_error
    reraise(exc_type, exc_value, tb)
  File "/home/ff7f/Desktop/microblog/flask/lib/python3.5/site-packages/flask/_compat.py", line 33, in reraise
    raise value
  File "/home/ff7f/Desktop/microblog/flask/lib/python3.5/site-packages/flask/helpers.py", line 323, in url_for
    force_external=external)
  File "/home/ff7f/Desktop/microblog/flask/lib/python3.5/site-packages/werkzeug/routing.py", line 1776, in build
    raise BuildError(endpoint, values, method, self)
werkzeug.routing.BuildError: Could not build url for endpoint 'user' with values ['page']. Did you forget to specify values ['username']?
2018-03-23 21:24:16,629 INFO: Microblog startup [in /home/ff7f/Desktop/microblog/app/__init__.py:36]
2018-03-23 21:58:14,305 INFO: Microblog startup [in /home/ff7f/Desktop/microblog/app/__init__.py:36]
